Workbook

Sheet Dashboard
B1: Amazon Sales Performance Dashboard
B2: September 2026 order data | Use the yellow dropdowns to filter | Amounts in ₹
B4: Category | C4: All | D4: Customer Location | E4: All | G4: Order Status | H4: All | I4: Month | J4: All
B6: Total Sales | C6: Total Orders | D6: Units Sold | E6: Avg Order Value | F6: Delivered % | G6: Cancelled % | H6: Pending %
B7: =SUMIFS(Cleaned_Data!$G$2:$G$501,Cleaned_Data!$D$2:$D$501,Pivots!$B$3,Cleaned_Data!$I$2:$I$501,Pivots!$B$4,Cleaned_Data!$N$2:$N$501,Pivots!$B$5,Cleaned_Data!$L$2:$L$501,Pivots!$B$6) -> 1564790 | C7: =COUNTIFS(Cleaned_Data!$D$2:$D$501,Pivots!$B$3,Cleaned_Data!$I$2:$I$501,Pivots!$B$4,Cleaned_Data!$N$2:$N$501,Pivots!$B$5,Cleaned_Data!$L$2:$L$501,Pivots!$B$6) -> 500 | D7: =SUMIFS(Cleaned_Data!$F$2:$F$501,Cleaned_Data!$D$2:$D$501,Pivots!$B$3,Cleaned_Data!$I$2:$I$501,Pivots!$B$4,Cleaned_Data!$N$2:$N$501,Pivots!$B$5,Cleaned_Data!$L$2:$L$501,Pivots!$B$6) -> 810 | E7: =IF(C7=0,0,B7/C7) -> 3129.58 | F7: =IF(COUNTIFS(Cleaned_Data!$D$2:$D$501,Pivots!$B$3,Cleaned_Data!$I$2:$I$501,Pivots!$B$4,Cleaned_Data!$L$2:$L$501,Pivots!$B$6)=0,0,COUNTIFS(Cleaned_Data!$D$2:$D$501,Pivots!$B$3,Cleaned_Data!$I$2:$I$501,Pivots!$B$4,Cleaned_Data!$L$2:$L$501,Pivots!$B$6,Cleaned_Data!$N$2:$N$501,"Delivered")/COUNTIFS(Cleaned_Data!$D$2:$D$501,Pivots!$B$3,Cleaned_Data!$I$2:$I$501,Pivots!$B$4,Cleaned_Data!$L$2:$L$501,Pivots!$B$6)) -> 0.764 | G7: =IF(COUNTIFS(Cleaned_Data!$D$2:$D$501,Pivots!$B$3,Cleaned_Data!$I$2:$I$501,Pivots!$B$4,Cleaned_Data!$L$2:$L$501,Pivots!$B$6)=0,0,COUNTIFS(Cleaned_Data!$D$2:$D$501,Pivots!$B$3,Cleaned_Data!$I$2:$I$501,Pivots!$B$4,Cleaned_Data!$L$2:$L$501,Pivots!$B$6,Cleaned_Data!$N$2:$N$501,"Cancelled")/COUNTIFS(Cleaned_Data!$D$2:$D$501,Pivots!$B$3,Cleaned_Data!$I$2:$I$501,Pivots!$B$4,Cleaned_Data!$L$2:$L$501,Pivots!$B$6)) -> 0.126 | H7: =IF(COUNTIFS(Cleaned_Data!$D$2:$D$501,Pivots!$B$3,Cleaned_Data!$I$2:$I$501,Pivots!$B$4,Cleaned_Data!$L$2:$L$501,Pivots!$B$6)=0,0,COUNTIFS(Cleaned_Data!$D$2:$D$501,Pivots!$B$3,Cleaned_Data!$I$2:$I$501,Pivots!$B$4,Cleaned_Data!$L$2:$L$501,Pivots!$B$6,Cleaned_Data!$N$2:$N$501,"Pending")/COUNTIFS(Cleaned_Data!$D$2:$D$501,Pivots!$B$3,Cleaned_Data!$I$2:$I$501,Pivots!$B$4,Cleaned_Data!$L$2:$L$501,Pivots!$B$6)) -> 0.11

Sheet Pivots
A1: Pivot Tables (formula-driven; respond to the Dashboard filters)
A3: Category criteria | B3: =IF(Dashboard!$C$4="All","*",Dashboard!$C$4) -> * | C3: '*' = All (wildcard). Set by the dropdowns on the Dashboard.
A4: Location criteria | B4: =IF(Dashboard!$E$4="All","*",Dashboard!$E$4) -> *
A5: Status criteria | B5: =IF(Dashboard!$H$4="All","*",Dashboard!$H$4) -> *
A6: Month criteria | B6: =IF(Dashboard!$J$4="All","*",Dashboard!$J$4) -> *
A9: Category-wise Total Sales | I9: Top 10 Customers by Total Spending
A10: Item | B10: Total Sales | C10: Orders | D10: Units Sold | E10: % of Sales | F10: Total Sales (all data) | I10: Rank | J10: Customer | K10: Total Sales | L10: Orders
A11: Electronics | B11: =SUMIFS(Cleaned_Data!$G$2:$G$501,Cleaned_Data!$D$2:$D$501,$A11,Cleaned_Data!$I$2:$I$501,$B$4,Cleaned_Data!$N$2:$N$501,$B$5,Cleaned_Data!$L$2:$L$501,$B$6) -> 595070 | C11: =COUNTIFS(Cleaned_Data!$D$2:$D$501,$A11,Cleaned_Data!$I$2:$I$501,$B$4,Cleaned_Data!$N$2:$N$501,$B$5,Cleaned_Data!$L$2:$L$501,$B$6) -> 148 | D11: =SUMIFS(Cleaned_Data!$F$2:$F$501,Cleaned_Data!$D$2:$D$501,$A11,Cleaned_Data!$I$2:$I$501,$B$4,Cleaned_Data!$N$2:$N$501,$B$5,Cleaned_Data!$L$2:$L$501,$B$6) -> 230 | E11: =IF($B$16=0,0,B11/$B$16) -> 0.38028745 | F11: =SUMIFS(Cleaned_Data!$G$2:$G$501,Cleaned_Data!$D$2:$D$501,$A11) -> 595070 | I11: 1 | J11: =INDEX($A$73:$A$132,MATCH(LARGE($G$73:$G$132,I11),$G$73:$G$132,0)) -> Anjali Verma | K11: =INDEX($B$73:$B$132,MATCH(LARGE($G$73:$G$132,I11),$G$73:$G$132,0)) -> 59983 | L11: =INDEX($C$73:$C$132,MATCH(LARGE($G$73:$G$132,I11),$G$73:$G$132,0)) -> 9
A12: Home & Kitchen | B12: =SUMIFS(Cleaned_Data!$G$2:$G$501,Cleaned_Data!$D$2:$D$501,$A12,Cleaned_Data!$I$2:$I$501,$B$4,Cleaned_Data!$N$2:$N$501,$B$5,Cleaned_Data!$L$2:$L$501,$B$6) -> 416310 | C12: =COUNTIFS(Cleaned_Data!$D$2:$D$501,$A12,Cleaned_Data!$I$2:$I$501,$B$4,Cleaned_Data!$N$2:$N$501,$B$5,Cleaned_Data!$L$2:$L$501,$B$6) -> 113 | D12: =SUMIFS(Cleaned_Data!$F$2:$F$501,Cleaned_Data!$D$2:$D$501,$A12,Cleaned_Data!$I$2:$I$501,$B$4,Cleaned_Data!$N$2:$N$501,$B$5,Cleaned_Data!$L$2:$L$501,$B$6) -> 190 | E12: =IF($B$16=0,0,B12/$B$16) -> 0.26604848 | F12: =SUMIFS(Cleaned_Data!$G$2:$G$501,Cleaned_Data!$D$2:$D$501,$A12) -> 416310 | I12: 2 | J12: =INDEX($A$73:$A$132,MATCH(LARGE($G$73:$G$132,I12),$G$73:$G$132,0)) -> Vikram Nair | K12: =INDEX($B$73:$B$132,MATCH(LARGE($G$73:$G$132,I12),$G$73:$G$132,0)) -> 53281 | L12: =INDEX($C$73:$C$132,MATCH(LARGE($G$73:$G$132,I12),$G$73:$G$132,0)) -> 11
A13: Footwear | B13: =SUMIFS(Cleaned_Data!$G$2:$G$501,Cleaned_Data!$D$2:$D$501,$A13,Cleaned_Data!$I$2:$I$501,$B$4,Cleaned_Data!$N$2:$N$501,$B$5,Cleaned_Data!$L$2:$L$501,$B$6) -> 356943 | C13: =COUNTIFS(Cleaned_Data!$D$2:$D$501,$A13,Cleaned_Data!$I$2:$I$501,$B$4,Cleaned_Data!$N$2:$N$501,$B$5,Cleaned_Data!$L$2:$L$501,$B$6) -> 97 | D13: =SUMIFS(Cleaned_Data!$F$2:$F$501,Cleaned_Data!$D$2:$D$501,$A13,Cleaned_Data!$I$2:$I$501,$B$4,Cleaned_Data!$N$2:$N$501,$B$5,Cleaned_Data!$L$2:$L$501,$B$6) -> 157 | E13: =IF($B$16=0,0,B13/$B$16) -> 0.2281092 | F13: =SUMIFS(Cleaned_Data!$G$2:$G$501,Cleaned_Data!$D$2:$D$501,$A13) -> 356943 | I13: 3 | J13: =INDEX($A$73:$A$132,MATCH(LARGE($G$73:$G$132,I13),$G$73:$G$132,0)) -> Ishaan Chopra | K13: =INDEX($B$73:$B$132,MATCH(LARGE($G$73:$G$132,I13),$G$73:$G$132,0)) -> 50384 | L13: =INDEX($C$73:$C$132,MATCH(LARGE($G$73:$G$132,I13),$G$73:$G$132,0)) -> 9
A14: Clothing | B14: =SUMIFS(Cleaned_Data!$G$2:$G$501,Cleaned_Data!$D$2:$D$501,$A14,Cleaned_Data!$I$2:$I$501,$B$4,Cleaned_Data!$N$2:$N$501,$B$5,Cleaned_Data!$L$2:$L$501,$B$6) -> 136083 | C14: =COUNTIFS(Cleaned_Data!$D$2:$D$501,$A14,Cleaned_Data!$I$2:$I$501,$B$4,Cleaned_Data!$N$2:$N$501,$B$5,Cleaned_Data!$L$2:$L$501,$B$6) -> 70 | D14: =SUMIFS(Cleaned_Data!$F$2:$F$501,Cleaned_Data!$D$2:$D$501,$A14,Cleaned_Data!$I$2:$I$501,$B$4,Cleaned_Data!$N$2:$N$501,$B$5,Cleaned_Data!$L$2:$L$501,$B$6) -> 117 | E14: =IF($B$16=0,0,B14/$B$16) -> 0.086965663 | F14: =SUMIFS(Cleaned_Data!$G$2:$G$501,Cleaned_Data!$D$2:$D$501,$A14) -> 136083 | I14: 4 | J14: =INDEX($A$73:$A$132,MATCH(LARGE($G$73:$G$132,I14),$G$73:$G$132,0)) -> Kavya Rao | K14: =INDEX($B$73:$B$132,MATCH(LARGE($G$73:$G$132,I14),$G$73:$G$132,0)) -> 45980 | L14: =INDEX($C$73:$C$132,MATCH(LARGE($G$73:$G$132,I14),$G$73:$G$132,0)) -> 10
A15: Books | B15: =SUMIFS(Cleaned_Data!$G$2:$G$501,Cleaned_Data!$D$2:$D$501,$A15,Cleaned_Data!$I$2:$I$501,$B$4,Cleaned_Data!$N$2:$N$501,$B$5,Cleaned_Data!$L$2:$L$501,$B$6) -> 60384 | C15: =COUNTIFS(Cleaned_Data!$D$2:$D$501,$A15,Cleaned_Data!$I$2:$I$501,$B$4,Cleaned_Data!$N$2:$N$501,$B$5,Cleaned_Data!$L$2:$L$501,$B$6) -> 72 | D15: =SUMIFS(Cleaned_Data!$F$2:$F$501,Cleaned_Data!$D$2:$D$501,$A15,Cleaned_Data!$I$2:$I$501,$B$4,Cleaned_Data!$N$2:$N$501,$B$5,Cleaned_Data!$L$2:$L$501,$B$6) -> 116 | E15: =IF($B$16=0,0,B15/$B$16) -> 0.038589204 | F15: =SUMIFS(Cleaned_Data!$G$2:$G$501,Cleaned_Data!$D$2:$D$501,$A15) -> 60384 | I15: 5 | J15: =INDEX($A$73:$A$132,MATCH(LARGE($G$73:$G$132,I15),$G$73:$G$132,0)) -> Rajesh Reddy | K15: =INDEX($B$73:$B$132,MATCH(LARGE($G$73:$G$132,I15),$G$73:$G$132,0)) -> 44481 | L15: =INDEX($C$73:$C$132,MATCH(LARGE($G$73:$G$132,I15),$G$73:$G$132,0)) -> 9
A16: Grand Total | B16: =SUM(B11:B15) -> 1564790 | C16: =SUM(C11:C15) -> 500 | D16: =SUM(D11:D15) -> 810 | E16: =SUM(E11:E15) -> 1 | F16: =SUM(F11:F15) -> 1564790 | I16: 6 | J16: =INDEX($A$73:$A$132,MATCH(LARGE($G$73:$G$132,I16),$G$73:$G$132,0)) -> Aditya Iyer | K16: =INDEX($B$73:$B$132,MATCH(LARGE($G$73:$G$132,I16),$G$73:$G$132,0)) -> 40576 | L16: =INDEX($C$73:$C$132,MATCH(LARGE($G$73:$G$132,I16),$G$73:$G$132,0)) -> 12
I17: 7 | J17: =INDEX($A$73:$A$132,MATCH(LARGE($G$73:$G$132,I17),$G$73:$G$132,0)) -> Nikhil Joshi | K17: =INDEX($B$73:$B$132,MATCH(LARGE($G$73:$G$132,I17),$G$73:$G$132,0)) -> 39683 | L17: =INDEX($C$73:$C$132,MATCH(LARGE($G$73:$G$132,I17),$G$73:$G$132,0)) -> 10
I18: 8 | J18: =INDEX($A$73:$A$132,MATCH(LARGE($G$73:$G$132,I18),$G$73:$G$132,0)) -> Sahil Sharma | K18: =INDEX($B$73:$B$132,MATCH(LARGE($G$73:$G$132,I18),$G$73:$G$132,0)) -> 39477 | L18: =INDEX($C$73:$C$132,MATCH(LARGE($G$73:$G$132,I18),$G$73:$G$132,0)) -> 12
A19: Product-wise Performance | I19: 9 | J19: =INDEX($A$73:$A$132,MATCH(LARGE($G$73:$G$132,I19),$G$73:$G$132,0)) -> Tanvi Iyer | K19: =INDEX($B$73:$B$132,MATCH(LARGE($G$73:$G$132,I19),$G$73:$G$132,0)) -> 39288 | L19: =INDEX($C$73:$C$132,MATCH(LARGE($G$73:$G$132,I19),$G$73:$G$132,0)) -> 8
A20: Item | B20: Total Sales | C20: Orders | D20: Units Sold | E20: % of Sales | F20: Total Sales (all data) | I20: 10 | J20: =INDEX($A$73:$A$132,MATCH(LARGE($G$73:$G$132,I20),$G$73:$G$132,0)) -> Nikhil Rao | K20: =INDEX($B$73:$B$132,MATCH(LARGE($G$73:$G$132,I20),$G$73:$G$132,0)) -> 37782 | L20: =INDEX($C$73:$C$132,MATCH(LARGE($G$73:$G$132,I20),$G$73:$G$132,0)) -> 10
A21: Smart Watch | B21: =SUMIFS(Cleaned_Data!$G$2:$G$501,Cleaned_Data!$C$2:$C$501,$A21,Cleaned_Data!$D$2:$D$501,$B$3,Cleaned_Data!$I$2:$I$501,$B$4,Cleaned_Data!$N$2:$N$501,$B$5,Cleaned_Data!$L$2:$L$501,$B$6) -> 234953 | C21: =COUNTIFS(Cleaned_Data!$C$2:$C$501,$A21,Cleaned_Data!$D$2:$D$501,$B$3,Cleaned_Data!$I$2:$I$501,$B$4,Cleaned_Data!$N$2:$N$501,$B$5,Cleaned_Data!$L$2:$L$501,$B$6) -> 33 | D21: =SUMIFS(Cleaned_Data!$F$2:$F$501,Cleaned_Data!$C$2:$C$501,$A21,Cleaned_Data!$D$2:$D$501,$B$3,Cleaned_Data!$I$2:$I$501,$B$4,Cleaned_Data!$N$2:$N$501,$B$5,Cleaned_Data!$L$2:$L$501,$B$6) -> 47 | E21: =IF($B$35=0,0,B21/$B$35) -> 0.15014986 | F21: =SUMIFS(Cleaned_Data!$G$2:$G$501,Cleaned_Data!$C$2:$C$501,$A21) -> 234953
A22: Running Shoes | B22: =SUMIFS(Cleaned_Data!$G$2:$G$501,Cleaned_Data!$C$2:$C$501,$A22,Cleaned_Data!$D$2:$D$501,$B$3,Cleaned_Data!$I$2:$I$501,$B$4,Cleaned_Data!$N$2:$N$501,$B$5,Cleaned_Data!$L$2:$L$501,$B$6) -> 214435 | C22: =COUNTIFS(Cleaned_Data!$C$2:$C$501,$A22,Cleaned_Data!$D$2:$D$501,$B$3,Cleaned_Data!$I$2:$I$501,$B$4,Cleaned_Data!$N$2:$N$501,$B$5,Cleaned_Data!$L$2:$L$501,$B$6) -> 36 | D22: =SUMIFS(Cleaned_Data!$F$2:$F$501,Cleaned_Data!$C$2:$C$501,$A22,Cleaned_Data!$D$2:$D$501,$B$3,Cleaned_Data!$I$2:$I$501,$B$4,Cleaned_Data!$N$2:$N$501,$B$5,Cleaned_Data!$L$2:$L$501,$B$6) -> 65 | E22: =IF($B$35=0,0,B22/$B$35) -> 0.13703756 | F22: =SUMIFS(Cleaned_Data!$G$2:$G$501,Cleaned_Data!$C$2:$C$501,$A22) -> 214435
A23: Mixer Grinder | B23: =SUMIFS(Cleaned_Data!$G$2:$G$501,Cleaned_Data!$C$2:$C$501,$A23,Cleaned_Data!$D$2:$D$501,$B$3,Cleaned_Data!$I$2:$I$501,$B$4,Cleaned_Data!$N$2:$N$501,$B$5,Cleaned_Data!$L$2:$L$501,$B$6) -> 188946 | C23: =COUNTIFS(Cleaned_Data!$C$2:$C$501,$A23,Cleaned_Data!$D$2:$D$501,$B$3,Cleaned_Data!$I$2:$I$501,$B$4,Cleaned_Data!$N$2:$N$501,$B$5,Cleaned_Data!$L$2:$L$501,$B$6) -> 29 | D23: =SUMIFS(Cleaned_Data!$F$2:$F$501,Cleaned_Data!$C$2:$C$501,$A23,Cleaned_Data!$D$2:$D$501,$B$3,Cleaned_Data!$I$2:$I$501,$B$4,Cleaned_Data!$N$2:$N$501,$B$5,Cleaned_Data!$L$2:$L$501,$B$6) -> 54 | E23: =IF($B$35=0,0,B23/$B$35) -> 0.12074847 | F23: =SUMIFS(Cleaned_Data!$G$2:$G$501,Cleaned_Data!$C$2:$C$501,$A23) -> 188946
A24: Wireless Earbuds | B24: =SUMIFS(Cleaned_Data!$G$2:$G$501,Cleaned_Data!$C$2:$C$501,$A24,Cleaned_Data!$D$2:$D$501,$B$3,Cleaned_Data!$I$2:$I$501,$B$4,Cleaned_Data!$N$2:$N$501,$B$5,Cleaned_Data!$L$2:$L$501,$B$6) -> 184926 | C24: =COUNTIFS(Cleaned_Data!$C$2:$C$501,$A24,Cleaned_Data!$D$2:$D$501,$B$3,Cleaned_Data!$I$2:$I$501,$B$4,Cleaned_Data!$N$2:$N$501,$B$5,Cleaned_Data!$L$2:$L$501,$B$6) -> 46 | D24: =SUMIFS(Cleaned_Data!$F$2:$F$501,Cleaned_Data!$C$2:$C$501,$A24,Cleaned_Data!$D$2:$D$501,$B$3,Cleaned_Data!$I$2:$I$501,$B$4,Cleaned_Data!$N$2:$N$501,$B$5,Cleaned_Data!$L$2:$L$501,$B$6) -> 74 | E24: =IF($B$35=0,0,B24/$B$35) -> 0.11817944 | F24: =SUMIFS(Cleaned_Data!$G$2:$G$501,Cleaned_Data!$C$2:$C$501,$A24) -> 184926
A25: Air Fryer | B25: =SUMIFS(Cleaned_Data!$G$2:$G$501,Cleaned_Data!$C$2:$C$501,$A25,Cleaned_Data!$D$2:$D$501,$B$3,Cleaned_Data!$I$2:$I$501,$B$4,Cleaned_Data!$N$2:$N$501,$B$5,Cleaned_Data!$L$2:$L$501,$B$6) -> 173971 | C25: =COUNTIFS(Cleaned_Data!$C$2:$C$501,$A25,Cleaned_Data!$D$2:$D$501,$B$3,Cleaned_Data!$I$2:$I$501,$B$4,Cleaned_Data!$N$2:$N$501,$B$5,Cleaned_Data!$L$2:$L$501,$B$6) -> 18 | D25: =SUMIFS(Cleaned_Data!$F$2:$F$501,Cleaned_Data!$C$2:$C$501,$A25,Cleaned_Data!$D$2:$D$501,$B$3,Cleaned_Data!$I$2:$I$501,$B$4,Cleaned_Data!$N$2:$N$501,$B$5,Cleaned_Data!$L$2:$L$501,$B$6) -> 29 | E25: =IF($B$35=0,0,B25/$B$35) -> 0.1111785 | F25: =SUMIFS(Cleaned_Data!$G$2:$G$501,Cleaned_Data!$C$2:$C$501,$A25) -> 173971
A26: Casual Sneakers | B26: =SUMIFS(Cleaned_Data!$G$2:$G$501,Cleaned_Data!$C$2:$C$501,$A26,Cleaned_Data!$D$2:$D$501,$B$3,Cleaned_Data!$I$2:$I$501,$B$4,Cleaned_Data!$N$2:$N$501,$B$5,Cleaned_Data!$L$2:$L$501,$B$6) -> 101154 | C26: =COUNTIFS(Cleaned_Data!$C$2:$C$501,$A26,Cleaned_Data!$D$2:$D$501,$B$3,Cleaned_Data!$I$2:$I$501,$B$4,Cleaned_Data!$N$2:$N$501,$B$5,Cleaned_Data!$L$2:$L$501,$B$6) -> 36 | D26: =SUMIFS(Cleaned_Data!$F$2:$F$501,Cleaned_Data!$C$2:$C$501,$A26,Cleaned_Data!$D$2:$D$501,$B$3,Cleaned_Data!$I$2:$I$501,$B$4,Cleaned_Data!$N$2:$N$501,$B$5,Cleaned_Data!$L$2:$L$501,$B$6) -> 46 | E26: =IF($B$35=0,0,B26/$B$35) -> 0.064643818 | F26: =SUMIFS(Cleaned_Data!$G$2:$G$501,Cleaned_Data!$C$2:$C$501,$A26) -> 101154
A27: Denim Jeans | B27: =SUMIFS(Cleaned_Data!$G$2:$G$501,Cleaned_Data!$C$2:$C$501,$A27,Cleaned_Data!$D$2:$D$501,$B$3,Cleaned_Data!$I$2:$I$501,$B$4,Cleaned_Data!$N$2:$N$501,$B$5,Cleaned_Data!$L$2:$L$501,$B$6) -> 98945 | C27: =COUNTIFS(Cleaned_Data!$C$2:$C$501,$A27,Cleaned_Data!$D$2:$D$501,$B$3,Cleaned_Data!$I$2:$I$501,$B$4,Cleaned_Data!$N$2:$N$501,$B$5,Cleaned_Data!$L$2:$L$501,$B$6) -> 33 | D27: =SUMIFS(Cleaned_Data!$F$2:$F$501,Cleaned_Data!$C$2:$C$501,$A27,Cleaned_Data!$D$2:$D$501,$B$3,Cleaned_Data!$I$2:$I$501,$B$4,Cleaned_Data!$N$2:$N$501,$B$5,Cleaned_Data!$L$2:$L$501,$B$6) -> 55 | E27: =IF($B$35=0,0,B27/$B$35) -> 0.063232127 | F27: =SUMIFS(Cleaned_Data!$G$2:$G$501,Cleaned_Data!$C$2:$C$501,$A27) -> 98945
A28: Bluetooth Speaker | B28: =SUMIFS(Cleaned_Data!$G$2:$G$501,Cleaned_Data!$C$2:$C$501,$A28,Cleaned_Data!$D$2:$D$501,$B$3,Cleaned_Data!$I$2:$I$501,$B$4,Cleaned_Data!$N$2:$N$501,$B$5,Cleaned_Data!$L$2:$L$501,$B$6) -> 95952 | C28: =COUNTIFS(Cleaned_Data!$C$2:$C$501,$A28,Cleaned_Data!$D$2:$D$501,$B$3,Cleaned_Data!$I$2:$I$501,$B$4,Cleaned_Data!$N$2:$N$501,$B$5,Cleaned_Data!$L$2:$L$501,$B$6) -> 30 | D28: =SUMIFS(Cleaned_Data!$F$2:$F$501,Cleaned_Data!$C$2:$C$501,$A28,Cleaned_Data!$D$2:$D$501,$B$3,Cleaned_Data!$I$2:$I$501,$B$4,Cleaned_Data!$N$2:$N$501,$B$5,Cleaned_Data!$L$2:$L$501,$B$6) -> 48 | E28: =IF($B$35=0,0,B28/$B$35) -> 0.06131941 | F28: =SUMIFS(Cleaned_Data!$G$2:$G$501,Cleaned_Data!$C$2:$C$501,$A28) -> 95952
A29: Power Bank | B29: =SUMIFS(Cleaned_Data!$G$2:$G$501,Cleaned_Data!$C$2:$C$501,$A29,Cleaned_Data!$D$2:$D$501,$B$3,Cleaned_Data!$I$2:$I$501,$B$4,Cleaned_Data!$N$2:$N$501,$B$5,Cleaned_Data!$L$2:$L$501,$B$6) -> 79239 | C29: =COUNTIFS(Cleaned_Data!$C$2:$C$501,$A29,Cleaned_Data!$D$2:$D$501,$B$3,Cleaned_Data!$I$2:$I$501,$B$4,Cleaned_Data!$N$2:$N$501,$B$5,Cleaned_Data!$L$2:$L$501,$B$6) -> 39 | D29: =SUMIFS(Cleaned_Data!$F$2:$F$501,Cleaned_Data!$C$2:$C$501,$A29,Cleaned_Data!$D$2:$D$501,$B$3,Cleaned_Data!$I$2:$I$501,$B$4,Cleaned_Data!$N$2:$N$501,$B$5,Cleaned_Data!$L$2:$L$501,$B$6) -> 61 | E29: =IF($B$35=0,0,B29/$B$35) -> 0.050638744 | F29: =SUMIFS(Cleaned_Data!$G$2:$G$501,Cleaned_Data!$C$2:$C$501,$A29) -> 79239
A30: Water Bottle | B30: =SUMIFS(Cleaned_Data!$G$2:$G$501,Cleaned_Data!$C$2:$C$501,$A30,Cleaned_Data!$D$2:$D$501,$B$3,Cleaned_Data!$I$2:$I$501,$B$4,Cleaned_Data!$N$2:$N$501,$B$5,Cleaned_Data!$L$2:$L$501,$B$6) -> 53393 | C30: =COUNTIFS(Cleaned_Data!$C$2:$C$501,$A30,Cleaned_Data!$D$2:$D$501,$B$3,Cleaned_Data!$I$2:$I$501,$B$4,Cleaned_Data!$N$2:$N$501,$B$5,Cleaned_Data!$L$2:$L$501,$B$6) -> 66 | D30: =SUMIFS(Cleaned_Data!$F$2:$F$501,Cleaned_Data!$C$2:$C$501,$A30,Cleaned_Data!$D$2:$D$501,$B$3,Cleaned_Data!$I$2:$I$501,$B$4,Cleaned_Data!$N$2:$N$501,$B$5,Cleaned_Data!$L$2:$L$501,$B$6) -> 107 | E30: =IF($B$35=0,0,B30/$B$35) -> 0.034121512 | F30: =SUMIFS(Cleaned_Data!$G$2:$G$501,Cleaned_Data!$C$2:$C$501,$A30) -> 53393
A31: Sandals | B31: =SUMIFS(Cleaned_Data!$G$2:$G$501,Cleaned_Data!$C$2:$C$501,$A31,Cleaned_Data!$D$2:$D$501,$B$3,Cleaned_Data!$I$2:$I$501,$B$4,Cleaned_Data!$N$2:$N$501,$B$5,Cleaned_Data!$L$2:$L$501,$B$6) -> 41354 | C31: =COUNTIFS(Cleaned_Data!$C$2:$C$501,$A31,Cleaned_Data!$D$2:$D$501,$B$3,Cleaned_Data!$I$2:$I$501,$B$4,Cleaned_Data!$N$2:$N$501,$B$5,Cleaned_Data!$L$2:$L$501,$B$6) -> 25 | D31: =SUMIFS(Cleaned_Data!$F$2:$F$501,Cleaned_Data!$C$2:$C$501,$A31,Cleaned_Data!$D$2:$D$501,$B$3,Cleaned_Data!$I$2:$I$501,$B$4,Cleaned_Data!$N$2:$N$501,$B$5,Cleaned_Data!$L$2:$L$501,$B$6) -> 46 | E31: =IF($B$35=0,0,B31/$B$35) -> 0.026427827 | F31: =SUMIFS(Cleaned_Data!$G$2:$G$501,Cleaned_Data!$C$2:$C$501,$A31) -> 41354
A32: Cotton T-Shirt | B32: =SUMIFS(Cleaned_Data!$G$2:$G$501,Cleaned_Data!$C$2:$C$501,$A32,Cleaned_Data!$D$2:$D$501,$B$3,Cleaned_Data!$I$2:$I$501,$B$4,Cleaned_Data!$N$2:$N$501,$B$5,Cleaned_Data!$L$2:$L$501,$B$6) -> 37138 | C32: =COUNTIFS(Cleaned_Data!$C$2:$C$501,$A32,Cleaned_Data!$D$2:$D$501,$B$3,Cleaned_Data!$I$2:$I$501,$B$4,Cleaned_Data!$N$2:$N$501,$B$5,Cleaned_Data!$L$2:$L$501,$B$6) -> 37 | D32: =SUMIFS(Cleaned_Data!$F$2:$F$501,Cleaned_Data!$C$2:$C$501,$A32,Cleaned_Data!$D$2:$D$501,$B$3,Cleaned_Data!$I$2:$I$501,$B$4,Cleaned_Data!$N$2:$N$501,$B$5,Cleaned_Data!$L$2:$L$501,$B$6) -> 62 | E32: =IF($B$35=0,0,B32/$B$35) -> 0.023733536 | F32: =SUMIFS(Cleaned_Data!$G$2:$G$501,Cleaned_Data!$C$2:$C$501,$A32) -> 37138
... A34: Self Help Book | B34: =SUMIFS(Cleaned_Data!$G$2:$G$501,Cleaned_Data!$C$2:$C$501,$A34,Cleaned_Data!$D$2:$D$501,$B$3,Cleaned_Data!$I$2:$I$501,$B$4,Cleaned_Data!$N$2:$N$501,$B$5,Cleaned_Data!$L$2:$L$501,$B$6) -> 27531 | C34: =COUNTIFS(Cleaned_Data!$C$2:$C$501,$A34,Cleaned_Data!$D$2:$D$501,$B$3,Cleaned_Data!$I$2:$I$501,$B$4,Cleaned_Data!$N$2:$N$501,$B$5,Cleaned_Data!$L$2:$L$501,$B$6) -> 42 | D34: =SUMIFS(Cleaned_Data!$F$2:$F$501,Cleaned_Data!$C$2:$C$501,$A34,Cleaned_Data!$D$2:$D$501,$B$3,Cleaned_Data!$I$2:$I$501,$B$4,Cleaned_Data!$N$2:$N$501,$B$5,Cleaned_Data!$L$2:$L$501,$B$6) -> 69 | E34: =IF($B$35=0,0,B34/$B$35) -> 0.017594054 | F34: =SUMIFS(Cleaned_Data!$G$2:$G$501,Cleaned_Data!$C$2:$C$501,$A34) -> 27531
A35: Grand Total | B35: =SUM(B21:B34) -> 1564790 | C35: =SUM(C21:C34) -> 500 | D35: =SUM(D21:D34) -> 810 | E35: =SUM(E21:E34) -> 1 | F35: =SUM(F21:F34) -> 1564790
A38: City-wise Total Sales
A39: Item | B39: Total Sales | C39: Orders | D39: Units Sold | E39: % of Sales | F39: Total Sales (all data)
A40: Mumbai | B40: =SUMIFS(Cleaned_Data!$G$2:$G$501,Cleaned_Data!$I$2:$I$501,$A40,Cleaned_Data!$D$2:$D$501,$B$3,Cleaned_Data!$N$2:$N$501,$B$5,Cleaned_Data!$L$2:$L$501,$B$6) -> 351454 | C40: =COUNTIFS(Cleaned_Data!$I$2:$I$501,$A40,Cleaned_Data!$D$2:$D$501,$B$3,Cleaned_Data!$N$2:$N$501,$B$5,Cleaned_Data!$L$2:$L$501,$B$6) -> 85 | D40: =SUMIFS(Cleaned_Data!$F$2:$F$501,Cleaned_Data!$I$2:$I$501,$A40,Cleaned_Data!$D$2:$D$501,$B$3,Cleaned_Data!$N$2:$N$501,$B$5,Cleaned_Data!$L$2:$L$501,$B$6) -> 146 | E40: =IF($B$50=0,0,B40/$B$50) -> 0.22460138 | F40: =SUMIFS(Cleaned_Data!$G$2:$G$501,Cleaned_Data!$I$2:$I$501,$A40) -> 351454
A41: Bangalore | B41: =SUMIFS(Cleaned_Data!$G$2:$G$501,Cleaned_Data!$I$2:$I$501,$A41,Cleaned_Data!$D$2:$D$501,$B$3,Cleaned_Data!$N$2:$N$501,$B$5,Cleaned_Data!$L$2:$L$501,$B$6) -> 296448 | C41: =COUNTIFS(Cleaned_Data!$I$2:$I$501,$A41,Cleaned_Data!$D$2:$D$501,$B$3,Cleaned_Data!$N$2:$N$501,$B$5,Cleaned_Data!$L$2:$L$501,$B$6) -> 97 | D41: =SUMIFS(Cleaned_Data!$F$2:$F$501,Cleaned_Data!$I$2:$I$501,$A41,Cleaned_Data!$D$2:$D$501,$B$3,Cleaned_Data!$N$2:$N$501,$B$5,Cleaned_Data!$L$2:$L$501,$B$6) -> 152 | E41: =IF($B$50=0,0,B41/$B$50) -> 0.18944906 | F41: =SUMIFS(Cleaned_Data!$G$2:$G$501,Cleaned_Data!$I$2:$I$501,$A41) -> 296448
A42: Hyderabad | B42: =SUMIFS(Cleaned_Data!$G$2:$G$501,Cleaned_Data!$I$2:$I$501,$A42,Cleaned_Data!$D$2:$D$501,$B$3,Cleaned_Data!$N$2:$N$501,$B$5,Cleaned_Data!$L$2:$L$501,$B$6) -> 236367 | C42: =COUNTIFS(Cleaned_Data!$I$2:$I$501,$A42,Cleaned_Data!$D$2:$D$501,$B$3,Cleaned_Data!$N$2:$N$501,$B$5,Cleaned_Data!$L$2:$L$501,$B$6) -> 83 | D42: =SUMIFS(Cleaned_Data!$F$2:$F$501,Cleaned_Data!$I$2:$I$501,$A42,Cleaned_Data!$D$2:$D$501,$B$3,Cleaned_Data!$N$2:$N$501,$B$5,Cleaned_Data!$L$2:$L$501,$B$6) -> 133 | E42: =IF($B$50=0,0,B42/$B$50) -> 0.1510535 | F42: =SUMIFS(Cleaned_Data!$G$2:$G$501,Cleaned_Data!$I$2:$I$501,$A42) -> 236367
A43: Delhi | B43: =SUMIFS(Cleaned_Data!$G$2:$G$501,Cleaned_Data!$I$2:$I$501,$A43,Cleaned_Data!$D$2:$D$501,$B$3,Cleaned_Data!$N$2:$N$501,$B$5,Cleaned_Data!$L$2:$L$501,$B$6) -> 206192 | C43: =COUNTIFS(Cleaned_Data!$I$2:$I$501,$A43,Cleaned_Data!$D$2:$D$501,$B$3,Cleaned_Data!$N$2:$N$501,$B$5,Cleaned_Data!$L$2:$L$501,$B$6) -> 69 | D43: =SUMIFS(Cleaned_Data!$F$2:$F$501,Cleaned_Data!$I$2:$I$501,$A43,Cleaned_Data!$D$2:$D$501,$B$3,Cleaned_Data!$N$2:$N$501,$B$5,Cleaned_Data!$L$2:$L$501,$B$6) -> 108 | E43: =IF($B$50=0,0,B43/$B$50) -> 0.13176976 | F43: =SUMIFS(Cleaned_Data!$G$2:$G$501,Cleaned_Data!$I$2:$I$501,$A43) -> 206192
A44: Pune | B44: =SUMIFS(Cleaned_Data!$G$2:$G$501,Cleaned_Data!$I$2:$I$501,$A44,Cleaned_Data!$D$2:$D$501,$B$3,Cleaned_Data!$N$2:$N$501,$B$5,Cleaned_Data!$L$2:$L$501,$B$6) -> 135923 | C44: =COUNTIFS(Cleaned_Data!$I$2:$I$501,$A44,Cleaned_Data!$D$2:$D$501,$B$3,Cleaned_Data!$N$2:$N$501,$B$5,Cleaned_Data!$L$2:$L$501,$B$6) -> 50 | D44: =SUMIFS(Cleaned_Data!$F$2:$F$501,Cleaned_Data!$I$2:$I$501,$A44,Cleaned_Data!$D$2:$D$501,$B$3,Cleaned_Data!$N$2:$N$501,$B$5,Cleaned_Data!$L$2:$L$501,$B$6) -> 77 | E44: =IF($B$50=0,0,B44/$B$50) -> 0.086863413 | F44: =SUMIFS(Cleaned_Data!$G$2:$G$501,Cleaned_Data!$I$2:$I$501,$A44) -> 135923
A45: Kolkata | B45: =SUMIFS(Cleaned_Data!$G$2:$G$501,Cleaned_Data!$I$2:$I$501,$A45,Cleaned_Data!$D$2:$D$501,$B$3,Cleaned_Data!$N$2:$N$501,$B$5,Cleaned_Data!$L$2:$L$501,$B$6) -> 90757 | C45: =COUNTIFS(Cleaned_Data!$I$2:$I$501,$A45,Cleaned_Data!$D$2:$D$501,$B$3,Cleaned_Data!$N$2:$N$501,$B$5,Cleaned_Data!$L$2:$L$501,$B$6) -> 29 | D45: =SUMIFS(Cleaned_Data!$F$2:$F$501,Cleaned_Data!$I$2:$I$501,$A45,Cleaned_Data!$D$2:$D$501,$B$3,Cleaned_Data!$N$2:$N$501,$B$5,Cleaned_Data!$L$2:$L$501,$B$6) -> 43 | E45: =IF($B$50=0,0,B45/$B$50) -> 0.057999476 | F45: =SUMIFS(Cleaned_Data!$G$2:$G$501,Cleaned_Data!$I$2:$I$501,$A45) -> 90757
A46: Lucknow | B46: =SUMIFS(Cleaned_Data!$G$2:$G$501,Cleaned_Data!$I$2:$I$501,$A46,Cleaned_Data!$D$2:$D$501,$B$3,Cleaned_Data!$N$2:$N$501,$B$5,Cleaned_Data!$L$2:$L$501,$B$6) -> 79755 | C46: =COUNTIFS(Cleaned_Data!$I$2:$I$501,$A46,Cleaned_Data!$D$2:$D$501,$B$3,Cleaned_Data!$N$2:$N$501,$B$5,Cleaned_Data!$L$2:$L$501,$B$6) -> 27 | D46: =SUMIFS(Cleaned_Data!$F$2:$F$501,Cleaned_Data!$I$2:$I$501,$A46,Cleaned_Data!$D$2:$D$501,$B$3,Cleaned_Data!$N$2:$N$501,$B$5,Cleaned_Data!$L$2:$L$501,$B$6) -> 45 | E46: =IF($B$50=0,0,B46/$B$50) -> 0.050968501 | F46: =SUMIFS(Cleaned_Data!$G$2:$G$501,Cleaned_Data!$I$2:$I$501,$A46) -> 79755
...

Sheet Cleaned_Data
A1: Order ID | B1: Date | C1: Product | D1: Category | E1: Price | F1: Quantity | G1: Total Sales | H1: Customer Name | I1: Customer Location | J1: Payment Method | K1: Order Status | L1: Month | M1: Day of Week | N1: Status Flag | O1: Validation
A2: =TRIM(Raw_Data!A2) -> AMZ-10052 | B2: =Raw_Data!B2 -> 46266 | C2: =PROPER(TRIM(Raw_Data!C2)) -> Mixer Grinder | D2: =TRIM(Raw_Data!D2) -> Home & Kitchen | E2: =Raw_Data!E2 -> 3499 | F2: =Raw_Data!F2 -> 1 | G2: =E2*F2 -> 3499 | H2: =PROPER(TRIM(Raw_Data!H2)) -> Vikram Joshi | I2: =PROPER(TRIM(Raw_Data!I2)) -> Hyderabad | J2: =TRIM(Raw_Data!J2) -> UPI | K2: =PROPER(TRIM(Raw_Data!K2)) -> Delivered | L2: =TEXT(B2,"MMM") -> Sep | M2: =TEXT(B2,"ddd") -> Tue | N2: =IF(K2="Delivered","Delivered",IF(K2="Cancelled","Cancelled","Pending")) -> Delivered | O2: =IF(ROUND(G2-Raw_Data!G2,2)=0,"OK","Corrected") -> OK
A3: =TRIM(Raw_Data!A3) -> AMZ-10123 | B3: =Raw_Data!B3 -> 46266 | C3: =PROPER(TRIM(Raw_Data!C3)) -> Self Help Book | D3: =TRIM(Raw_Data!D3) -> Books | E3: =Raw_Data!E3 -> 399 | F3: =Raw_Data!F3 -> 3 | G3: =E3*F3 -> 1197 | H3: =PROPER(TRIM(Raw_Data!H3)) -> Vikram Iyer | I3: =PROPER(TRIM(Raw_Data!I3)) -> Bangalore | J3: =TRIM(Raw_Data!J3) -> Debit Card | K3: =PROPER(TRIM(Raw_Data!K3)) -> Delivered | L3: =TEXT(B3,"MMM") -> Sep | M3: =TEXT(B3,"ddd") -> Tue | N3: =IF(K3="Delivered","Delivered",IF(K3="Cancelled","Cancelled","Pending")) -> Delivered | O3: =IF(ROUND(G3-Raw_Data!G3,2)=0,"OK","Corrected") -> OK
A4: =TRIM(Raw_Data!A4) -> AMZ-10196 | B4: =Raw_Data!B4 -> 46266 | C4: =PROPER(TRIM(Raw_Data!C4)) -> Water Bottle | D4: =TRIM(Raw_Data!D4) -> Home & Kitchen | E4: =Raw_Data!E4 -> 499 | F4: =Raw_Data!F4 -> 2 | G4: =E4*F4 -> 998 | H4: =PROPER(TRIM(Raw_Data!H4)) -> Priya Das | I4: =PROPER(TRIM(Raw_Data!I4)) -> Hyderabad | J4: =TRIM(Raw_Data!J4) -> Debit Card | K4: =PROPER(TRIM(Raw_Data!K4)) -> Delivered | L4: =TEXT(B4,"MMM") -> Sep | M4: =TEXT(B4,"ddd") -> Tue | N4: =IF(K4="Delivered","Delivered",IF(K4="Cancelled","Cancelled","Pending")) -> Delivered | O4: =IF(ROUND(G4-Raw_Data!G4,2)=0,"OK","Corrected") -> OK
A5: =TRIM(Raw_Data!A5) -> AMZ-10245 | B5: =Raw_Data!B5 -> 46266 | C5: =PROPER(TRIM(Raw_Data!C5)) -> Self Help Book | D5: =TRIM(Raw_Data!D5) -> Books | E5: =Raw_Data!E5 -> 399 | F5: =Raw_Data!F5 -> 3 | G5: =E5*F5 -> 1197 | H5: =PROPER(TRIM(Raw_Data!H5)) -> Vivaan Sharma | I5: =PROPER(TRIM(Raw_Data!I5)) -> Mumbai | J5: =TRIM(Raw_Data!J5) -> Credit Card | K5: =PROPER(TRIM(Raw_Data!K5)) -> Delivered | L5: =TEXT(B5,"MMM") -> Sep | M5: =TEXT(B5,"ddd") -> Tue | N5: =IF(K5="Delivered","Delivered",IF(K5="Cancelled","Cancelled","Pending")) -> Delivered | O5: =IF(ROUND(G5-Raw_Data!G5,2)=0,"OK","Corrected") -> OK
A6: =TRIM(Raw_Data!A6) -> AMZ-10252 | B6: =Raw_Data!B6 -> 46266 | C6: =PROPER(TRIM(Raw_Data!C6)) -> Cotton T-Shirt | D6: =TRIM(Raw_Data!D6) -> Clothing | E6: =Raw_Data!E6 -> 599 | F6: =Raw_Data!F6 -> 1 | G6: =E6*F6 -> 599 | H6: =PROPER(TRIM(Raw_Data!H6)) -> Priya Chopra | I6: =PROPER(TRIM(Raw_Data!I6)) -> Bangalore | J6: =TRIM(Raw_Data!J6) -> Debit Card | K6: =PROPER(TRIM(Raw_Data!K6)) -> Delivered | L6: =TEXT(B6,"MMM") -> Sep | M6: =TEXT(B6,"ddd") -> Tue | N6: =IF(K6="Delivered","Delivered",IF(K6="Cancelled","Cancelled","Pending")) -> Delivered | O6: =IF(ROUND(G6-Raw_Data!G6,2)=0,"OK","Corrected") -> OK
A7: =TRIM(Raw_Data!A7) -> AMZ-10255 | B7: =Raw_Data!B7 -> 46266 | C7: =PROPER(TRIM(Raw_Data!C7)) -> Sandals | D7: =TRIM(Raw_Data!D7) -> Footwear | E7: =Raw_Data!E7 -> 899 | F7: =Raw_Data!F7 -> 4 | G7: =E7*F7 -> 3596 | H7: =PROPER(TRIM(Raw_Data!H7)) -> Priya Das | I7: =PROPER(TRIM(Raw_Data!I7)) -> Hyderabad | J7: =TRIM(Raw_Data!J7) -> Credit Card | K7: =PROPER(TRIM(Raw_Data!K7)) -> Delivered | L7: =TEXT(B7,"MMM") -> Sep | M7: =TEXT(B7,"ddd") -> Tue | N7: =IF(K7="Delivered","Delivered",IF(K7="Cancelled","Cancelled","Pending")) -> Delivered | O7: =IF(ROUND(G7-Raw_Data!G7,2)=0,"OK","Corrected") -> OK
A8: =TRIM(Raw_Data!A9) -> AMZ-10301 | B8: =Raw_Data!B9 -> 46266 | C8: =PROPER(TRIM(Raw_Data!C9)) -> Sandals | D8: =TRIM(Raw_Data!D9) -> Footwear | E8: =Raw_Data!E9 -> 899 | F8: =Raw_Data!F9 -> 3 | G8: =E8*F8 -> 2697 | H8: =PROPER(TRIM(Raw_Data!H9)) -> Nikhil Reddy | I8: =PROPER(TRIM(Raw_Data!I9)) -> Chennai | J8: =TRIM(Raw_Data!J9) -> UPI | K8: =PROPER(TRIM(Raw_Data!K9)) -> Delivered | L8: =TEXT(B8,"MMM") -> Sep | M8: =TEXT(B8,"ddd") -> Tue | N8: =IF(K8="Delivered","Delivered",IF(K8="Cancelled","Cancelled","Pending")) -> Delivered | O8: =IF(ROUND(G8-Raw_Data!G9,2)=0,"OK","Corrected") -> OK
A9: =TRIM(Raw_Data!A11) -> AMZ-10364 | B9: =Raw_Data!B11 -> 46266 | C9: =PROPER(TRIM(Raw_Data!C11)) -> Water Bottle | D9: =TRIM(Raw_Data!D11) -> Home & Kitchen | E9: =Raw_Data!E11 -> 499 | F9: =Raw_Data!F11 -> 3 | G9: =E9*F9 -> 1497 | H9: =PROPER(TRIM(Raw_Data!H11)) -> Vivaan Das | I9: =PROPER(TRIM(Raw_Data!I11)) -> Ahmedabad | J9: =TRIM(Raw_Data!J11) -> UPI | K9: =PROPER(TRIM(Raw_Data!K11)) -> Delivered | L9: =TEXT(B9,"MMM") -> Sep | M9: =TEXT(B9,"ddd") -> Tue | N9: =IF(K9="Delivered","Delivered",IF(K9="Cancelled","Cancelled","Pending")) -> Delivered | O9: =IF(ROUND(G9-Raw_Data!G11,2)=0,"OK","Corrected") -> OK
A10: =TRIM(Raw_Data!A12) -> AMZ-10414 | B10: =Raw_Data!B12 -> 46266 | C10: =PROPER(TRIM(Raw_Data!C12)) -> Air Fryer | D10: =TRIM(Raw_Data!D12) -> Home & Kitchen | E10: =Raw_Data!E12 -> 5999 | F10: =Raw_Data!F12 -> 1 | G10: =E10*F10 -> 5999 | H10: =PROPER(TRIM(Raw_Data!H12)) -> Aditya Singh | I10: =PROPER(TRIM(Raw_Data!I12)) -> Delhi | J10: =TRIM(Raw_Data!J12) -> UPI | K10: =PROPER(TRIM(Raw_Data!K12)) -> Delivered | L10: =TEXT(B10,"MMM") -> Sep | M10: =TEXT(B10,"ddd") -> Tue | N10: =IF(K10="Delivered","Delivered",IF(K10="Cancelled","Cancelled","Pending")) -> Delivered | O10: =IF(ROUND(G10-Raw_Data!G12,2)=0,"OK","Corrected") -> OK
A11: =TRIM(Raw_Data!A13) -> AMZ-10484 | B11: =Raw_Data!B13 -> 46266 | C11: =PROPER(TRIM(Raw_Data!C13)) -> Water Bottle | D11: =TRIM(Raw_Data!D13) -> Home & Kitchen | E11: =Raw_Data!E13 -> 499 | F11: =Raw_Data!F13 -> 1 | G11: =E11*F11 -> 499 | H11: =PROPER(TRIM(Raw_Data!H13)) -> Priya Iyer | I11: =PROPER(TRIM(Raw_Data!I13)) -> Delhi | J11: =TRIM(Raw_Data!J13) -> Debit Card | K11: =PROPER(TRIM(Raw_Data!K13)) -> Delivered | L11: =TEXT(B11,"MMM") -> Sep | M11: =TEXT(B11,"ddd") -> Tue | N11: =IF(K11="Delivered","Delivered",IF(K11="Cancelled","Cancelled","Pending")) -> Delivered | O11: =IF(ROUND(G11-Raw_Data!G13,2)=0,"OK","Corrected") -> OK
A12: =TRIM(Raw_Data!A14) -> AMZ-10113 | B12: =Raw_Data!B14 -> 46267 | C12: =PROPER(TRIM(Raw_Data!C14)) -> Cotton T-Shirt | D12: =TRIM(Raw_Data!D14) -> Clothing | E12: =Raw_Data!E14 -> 599 | F12: =Raw_Data!F14 -> 2 | G12: =E12*F12 -> 1198 | H12: =PROPER(TRIM(Raw_Data!H14)) -> Aditya Rao | I12: =PROPER(TRIM(Raw_Data!I14)) -> Delhi | J12: =TRIM(Raw_Data!J14) -> UPI | K12: =PROPER(TRIM(Raw_Data!K14)) -> Delivered | L12: =TEXT(B12,"MMM") -> Sep | M12: =TEXT(B12,"ddd") -> Wed | N12: =IF(K12="Delivered","Delivered",IF(K12="Cancelled","Cancelled","Pending")) -> Delivered | O12: =IF(ROUND(G12-Raw_Data!G14,2)=0,"OK","Corrected") -> OK
A13: =TRIM(Raw_Data!A15) -> AMZ-10145 | B13: =Raw_Data!B15 -> 46267 | C13: =PROPER(TRIM(Raw_Data!C15)) -> Cotton T-Shirt | D13: =TRIM(Raw_Data!D15) -> Clothing | E13: =Raw_Data!E15 -> 599 | F13: =Raw_Data!F15 -> 1 | G13: =E13*F13 -> 599 | H13: =PROPER(TRIM(Raw_Data!H15)) -> Tanvi Joshi | I13: =PROPER(TRIM(Raw_Data!I15)) -> Bangalore | J13: =TRIM(Raw_Data!J15) -> UPI | K13: =PROPER(TRIM(Raw_Data!K15)) -> Delivered | L13: =TEXT(B13,"MMM") -> Sep | M13: =TEXT(B13,"ddd") -> Wed | N13: =IF(K13="Delivered","Delivered",IF(K13="Cancelled","Cancelled","Pending")) -> Delivered | O13: =IF(ROUND(G13-Raw_Data!G15,2)=0,"OK","Corrected") -> OK
A14: =TRIM(Raw_Data!A16) -> AMZ-10182 | B14: =Raw_Data!B16 -> 46267 | C14: =PROPER(TRIM(Raw_Data!C16)) -> Air Fryer | D14: =TRIM(Raw_Data!D16) -> Home & Kitchen | E14: =Raw_Data!E16 -> 5999 | F14: =Raw_Data!F16 -> 1 | G14: =E14*F14 -> 5999 | H14: =PROPER(TRIM(Raw_Data!H16)) -> Aarav Joshi | I14: =PROPER(TRIM(Raw_Data!I16)) -> Pune | J14: =TRIM(Raw_Data!J16) -> Net Banking | K14: =PROPER(TRIM(Raw_Data!K16)) -> Cancelled | L14: =TEXT(B14,"MMM") -> Sep | M14: =TEXT(B14,"ddd") -> Wed | N14: =IF(K14="Delivered","Delivered",IF(K14="Cancelled","Cancelled","Pending")) -> Cancelled | O14: =IF(ROUND(G14-Raw_Data!G16,2)=0,"OK","Corrected") -> OK
A15: =TRIM(Raw_Data!A17) -> AMZ-10204 | B15: =Raw_Data!B17 -> 46267 | C15: =PROPER(TRIM(Raw_Data!C17)) -> Mixer Grinder | D15: =TRIM(Raw_Data!D17) -> Home & Kitchen | E15: =Raw_Data!E17 -> 3499 | F15: =Raw_Data!F17 -> 1 | G15: =E15*F15 -> 3499 | H15: =PROPER(TRIM(Raw_Data!H17)) -> Kavya Patel | I15: =PROPER(TRIM(Raw_Data!I17)) -> Hyderabad | J15: =TRIM(Raw_Data!J17) -> UPI | K15: =PROPER(TRIM(Raw_Data!K17)) -> Shipped | L15: =TEXT(B15,"MMM") -> Sep | M15: =TEXT(B15,"ddd") -> Wed | N15: =IF(K15="Delivered","Delivered",IF(K15="Cancelled","Cancelled","Pending")) -> Pending | O15: =IF(ROUND(G15-Raw_Data!G17,2)=0,"OK","Corrected") -> OK
A16: =TRIM(Raw_Data!A18) -> AMZ-10237 | B16: =Raw_Data!B18 -> 46267 | C16: =PROPER(TRIM(Raw_Data!C18)) -> Self Help Book | D16: =TRIM(Raw_Data!D18) -> Books | E16: =Raw_Data!E18 -> 399 | F16: =Raw_Data!F18 -> 1 | G16: =E16*F16 -> 399 | H16: =PROPER(TRIM(Raw_Data!H18)) -> Nikhil Kulkarni | I16: =PROPER(TRIM(Raw_Data!I18)) -> Pune | J16: =TRIM(Raw_Data!J18) -> Credit Card | K16: =PROPER(TRIM(Raw_Data!K18)) -> Delivered | L16: =TEXT(B16,"MMM") -> Sep | M16: =TEXT(B16,"ddd") -> Wed | N16: =IF(K16="Delivered","Delivered",IF(K16="Cancelled","Cancelled","Pending")) -> Delivered | O16: =IF(ROUND(G16-Raw_Data!G18,2)=0,"OK","Corrected") -> OK
A17: =TRIM(Raw_Data!A19) -> AMZ-10260 | B17: =Raw_Data!B19 -> 46267 | C17: =PROPER(TRIM(Raw_Data!C19)) -> Wireless Earbuds | D17: =TRIM(Raw_Data!D19) -> Electronics | E17: =Raw_Data!E19 -> 2499 | F17: =Raw_Data!F19 -> 2 | G17: =E17*F17 -> 4998 | H17: =PROPER(TRIM(Raw_Data!H19)) -> Nikhil Patel | I17: =PROPER(TRIM(Raw_Data!I19)) -> Hyderabad | J17: =TRIM(Raw_Data!J19) -> UPI | K17: =PROPER(TRIM(Raw_Data!K19)) -> Delivered | L17: =TEXT(B17,"MMM") -> Sep | M17: =TEXT(B17,"ddd") -> Wed | N17: =IF(K17="Delivered","Delivered",IF(K17="Cancelled","Cancelled","Pending")) -> Delivered | O17: =IF(ROUND(G17-Raw_Data!G19,2)=0,"OK","Corrected") -> OK
A18: =TRIM(Raw_Data!A20) -> AMZ-10269 | B18: =Raw_Data!B20 -> 46267 | C18: =PROPER(TRIM(Raw_Data!C20)) -> Denim Jeans | D18: =TRIM(Raw_Data!D20) -> Clothing | E18: =Raw_Data!E20 -> 1799 | F18: =Raw_Data!F20 -> 1 | G18: =E18*F18 -> 1799 | H18: =PROPER(TRIM(Raw_Data!H20)) -> Tanvi Joshi | I18: =PROPER(TRIM(Raw_Data!I20)) -> Bangalore | J18: =TRIM(Raw_Data!J20) -> UPI | K18: =PROPER(TRIM(Raw_Data!K20)) -> Delivered | L18: =TEXT(B18,"MMM") -> Sep | M18: =TEXT(B18,"ddd") -> Wed | N18: =IF(K18="Delivered","Delivered",IF(K18="Cancelled","Cancelled","Pending")) -> Delivered | O18: =IF(ROUND(G18-Raw_Data!G20,2)=0,"OK","Corrected") -> OK
A19: =TRIM(Raw_Data!A21) -> AMZ-10272 | B19: =Raw_Data!B21 -> 46267 | C19: =PROPER(TRIM(Raw_Data!C21)) -> Running Shoes | D19: =TRIM(Raw_Data!D21) -> Footwear | E19: =Raw_Data!E21 -> 3299 | F19: =Raw_Data!F21 -> 1 | G19: =E19*F19 -> 3299 | H19: =PROPER(TRIM(Raw_Data!H21)) -> Priya Iyer | I19: =PROPER(TRIM(Raw_Data!I21)) -> Delhi | J19: =TRIM(Raw_Data!J21) -> Debit Card | K19: =PROPER(TRIM(Raw_Data!K21)) -> Delivered | L19: =TEXT(B19,"MMM") -> Sep | M19: =TEXT(B19,"ddd") -> Wed | N19: =IF(K19="Delivered","Delivered",IF(K19="Cancelled","Cancelled","Pending")) -> Delivered | O19: =IF(ROUND(G19-Raw_Data!G21,2)=0,"OK","Corrected") -> OK
A20: =TRIM(Raw_Data!A22) -> AMZ-10291 | B20: =Raw_Data!B22 -> 46267 | C20: =PROPER(TRIM(Raw_Data!C22)) -> Mixer Grinder | D20: =TRIM(Raw_Data!D22) -> Home & Kitchen | E20: =Raw_Data!E22 -> 3499 | F20: =Raw_Data!F22 -> 2 | G20: =E20*F20 -> 6998 | H20: =PROPER(TRIM(Raw_Data!H22)) -> Priya Iyer | I20: =PROPER(TRIM(Raw_Data!I22)) -> Delhi | J20: =TRIM(Raw_Data!J22) -> Cash On Delivery | K20: =PROPER(TRIM(Raw_Data!K22)) -> Delivered | L20: =TEXT(B20,"MMM") -> Sep | M20: =TEXT(B20,"ddd") -> Wed | N20: =IF(K20="Delivered","Delivered",IF(K20="Cancelled","Cancelled","Pending")) -> Delivered | O20: =IF(ROUND(G20-Raw_Data!G22,2)=0,"OK","Corrected") -> OK
... A63: =TRIM(Raw_Data!A65) -> AMZ-10317 | B63: =Raw_Data!B65 -> 46269 | C63: =PROPER(TRIM(Raw_Data!C65)) -> Power Bank | D63: =TRIM(Raw_Data!D65) -> Electronics | E63: =Raw_Data!E65 -> 1299 | F63: =Raw_Data!F65 -> 1 | G63: =E63*F63 -> 1299 | H63: =PROPER(TRIM(Raw_Data!H65)) -> Sneha Reddy | I63: =PROPER(TRIM(Raw_Data!I65)) -> Pune | J63: =TRIM(Raw_Data!J65) -> UPI | K63: =PROPER(TRIM(Raw_Data!K65)) -> Delivered | L63: =TEXT(B63,"MMM") -> Sep | M63: =TEXT(B63,"ddd") -> Fri | N63: =IF(K63="Delivered","Delivered",IF(K63="Cancelled","Cancelled","Pending")) -> Delivered | O63: =IF(ROUND(G63-Raw_Data!G65,2)=0,"OK","Corrected") -> OK
A64: =TRIM(Raw_Data!A67) -> AMZ-10363 | B64: =Raw_Data!B67 -> 46269 | C64: =PROPER(TRIM(Raw_Data!C67)) -> Bluetooth Speaker | D64: =TRIM(Raw_Data!D67) -> Electronics | E64: =Raw_Data!E67 -> 1999 | F64: =Raw_Data!F67 -> 3 | G64: =E64*F64 -> 5997 | H64: =PROPER(TRIM(Raw_Data!H67)) -> Tanvi Gupta | I64: =PROPER(TRIM(Raw_Data!I67)) -> Hyderabad | J64: =TRIM(Raw_Data!J67) -> UPI | K64: =PROPER(TRIM(Raw_Data!K67)) -> Delivered | L64: =TEXT(B64,"MMM") -> Sep | M64: =TEXT(B64,"ddd") -> Fri | N64: =IF(K64="Delivered","Delivered",IF(K64="Cancelled","Cancelled","Pending")) -> Delivered | O64: =IF(ROUND(G64-Raw_Data!G67,2)=0,"OK","Corrected") -> OK
A65: =TRIM(Raw_Data!A68) -> AMZ-10379 | B65: =Raw_Data!B68 -> 46269 | C65: =PROPER(TRIM(Raw_Data!C68)) -> Bluetooth Speaker | D65: =TRIM(Raw_Data!D68) -> Electronics | E65: =Raw_Data!E68 -> 1999 | F65: =Raw_Data!F68 -> 1 | G65: =E65*F65 -> 1999 | H65: =PROPER(TRIM(Raw_Data!H68)) -> Suresh Nair | I65: =PROPER(TRIM(Raw_Data!I68)) -> Bangalore | J65: =TRIM(Raw_Data!J68) -> Debit Card | K65: =PROPER(TRIM(Raw_Data!K68)) -> Delivered | L65: =TEXT(B65,"MMM") -> Sep | M65: =TEXT(B65,"ddd") -> Fri | N65: =IF(K65="Delivered","Delivered",IF(K65="Cancelled","Cancelled","Pending")) -> Delivered | O65: =IF(ROUND(G65-Raw_Data!G68,2)=0,"OK","Corrected") -> OK
A66: =TRIM(Raw_Data!A69) -> AMZ-10382 | B66: =Raw_Data!B69 -> 46269 | C66: =PROPER(TRIM(Raw_Data!C69)) -> Running Shoes | D66: =TRIM(Raw_Data!D69) -> Footwear | E66: =Raw_Data!E69 -> 3299 | F66: =Raw_Data!F69 -> 3 | G66: =E66*F66 -> 9897 | H66: =PROPER(TRIM(Raw_Data!H69)) -> Nikhil Patel | I66: =PROPER(TRIM(Raw_Data!I69)) -> Hyderabad | J66: =TRIM(Raw_Data!J69) -> Cash On Delivery | K66: =PROPER(TRIM(Raw_Data!K69)) -> Delivered | L66: =TEXT(B66,"MMM") -> Sep | M66: =TEXT(B66,"ddd") -> Fri | N66: =IF(K66="Delivered","Delivered",IF(K66="Cancelled","Cancelled","Pending")) -> Delivered | O66: =IF(ROUND(G66-Raw_Data!G69,2)=0,"OK","Corrected") -> OK
A67: =TRIM(Raw_Data!A70) -> AMZ-10412 | B67: =Raw_Data!B70 -> 46269 | C67: =PROPER(TRIM(Raw_Data!C70)) -> Smart Watch | D67: =TRIM(Raw_Data!D70) -> Electronics | E67: =Raw_Data!E70 -> 4999 | F67: =Raw_Data!F70 -> 1 | G67: =E67*F67 -> 4999 | H67: =PROPER(TRIM(Raw_Data!H70)) -> Meera Singh | I67: =PROPER(TRIM(Raw_Data!I70)) -> Hyderabad | J67: =TRIM(Raw_Data!J70) -> UPI | K67: =PROPER(TRIM(Raw_Data!K70)) -> Shipped | L67: =TEXT(B67,"MMM") -> Sep | M67: =TEXT(B67,"ddd") -> Fri | N67: =IF(K67="Delivered","Delivered",IF(K67="Cancelled","Cancelled","Pending")) -> Pending | O67: =IF(ROUND(G67-Raw_Data!G70,2)=0,"OK","Corrected") -> OK
A68: =TRIM(Raw_Data!A71) -> AMZ-10482 | B68: =Raw_Data!B71 -> 46269 | C68: =PROPER(TRIM(Raw_Data!C71)) -> Power Bank | D68: =TRIM(Raw_Data!D71) -> Electronics | E68: =Raw_Data!E71 -> 1299 | F68: =Raw_Data!F71 -> 1 | G68: =E68*F68 -> 1299 | H68: =PROPER(TRIM(Raw_Data!H71)) -> Tanvi Verma | I68: =PROPER(TRIM(Raw_Data!I71)) -> Kolkata | J68: =TRIM(Raw_Data!J71) -> UPI | K68: =PROPER(TRIM(Raw_Data!K71)) -> Delivered | L68: =TEXT(B68,"MMM") -> Sep | M68: =TEXT(B68,"ddd") -> Fri | N68: =IF(K68="Delivered","Delivered",IF(K68="Cancelled","Cancelled","Pending")) -> Delivered | O68: =IF(ROUND(G68-Raw_Data!G71,2)=0,"OK","Corrected") -> OK
A69: =TRIM(Raw_Data!A72) -> AMZ-10486 | B69: =Raw_Data!B72 -> 46269 | C69: =PROPER(TRIM(Raw_Data!C72)) -> Casual Sneakers | D69: =TRIM(Raw_Data!D72) -> Footwear | E69: =Raw_Data!E72 -> 2199 | F69: =Raw_Data!F72 -> 1 | G69: =E69*F69 -> 2199 | H69: =PROPER(TRIM(Raw_Data!H72)) -> Vivaan Iyer | I69: =PROPER(TRIM(Raw_Data!I72)) -> Pune | J69: =TRIM(Raw_Data!J72) -> UPI | K69: =PROPER(TRIM(Raw_Data!K72)) -> Delivered | L69: =TEXT(B69,"MMM") -> Sep | M69: =TEXT(B69,"ddd") -> Fri | N69: =IF(K69="Delivered","Delivered",IF(K69="Cancelled","Cancelled","Pending")) -> Delivered | O69: =IF(ROUND(G69-Raw_Data!G72,2)=0,"OK","Corrected") -> OK
A70: =TRIM(Raw_Data!A73) -> AMZ-10491 | B70: =Raw_Data!B73 -> 46269 | C70: =PROPER(TRIM(Raw_Data!C73)) -> Self Help Book | D70: =TRIM(Raw_Data!D73) -> Books | E70: =Raw_Data!E73 -> 399 | F70: =Raw_Data!F73 -> 1 | G70: =E70*F70 -> 399 | H70: =PROPER(TRIM(Raw_Data!H73)) -> Neha Kulkarni | I70: =PROPER(TRIM(Raw_Data!I73)) -> Delhi | J70: =TRIM(Raw_Data!J73) -> UPI | K70: =PROPER(TRIM(Raw_Data!K73)) -> Delivered | L70: =TEXT(B70,"MMM") -> Sep | M70: =TEXT(B70,"ddd") -> Fri | N70: =IF(K70="Delivered","Delivered",IF(K70="Cancelled","Cancelled","Pending")) -> Delivered | O70: =IF(ROUND(G70-Raw_Data!G73,2)=0,"OK","Corrected") -> OK
A71: =TRIM(Raw_Data!A74) -> AMZ-10500 | B71: =Raw_Data!B74 -> 46269 | C71: =PROPER(TRIM(Raw_Data!C74)) -> Wireless Earbuds | D71: =TRIM(Raw_Data!D74) -> Electronics | E71: =Raw_Data!E74 -> 2499 | F71: =Raw_Data!F74 -> 1 | G71: =E71*F71 -> 2499 | H71: =PROPER(TRIM(Raw_Data!H74)) -> Nikhil Joshi | I71: =PROPER(TRIM(Raw_Data!I74)) -> Lucknow | J71: =TRIM(Raw_Data!J74) -> Credit Card | K71: =PROPER(TRIM(Raw_Data!K74)) -> Delivered | L71: =TEXT(B71,"MMM") -> Sep | M71: =TEXT(B71,"ddd") -> Fri | N71: =IF(K71="Delivered","Delivered",IF(K71="Cancelled","Cancelled","Pending")) -> Delivered | O71: =IF(ROUND(G71-Raw_Data!G74,2)=0,"OK","Corrected") -> OK
A72: =TRIM(Raw_Data!A75) -> AMZ-10002 | B72: =Raw_Data!B75 -> 46270 | C72: =PROPER(TRIM(Raw_Data!C75)) -> Denim Jeans | D72: =TRIM(Raw_Data!D75) -> Clothing | E72: =Raw_Data!E75 -> 1799 | F72: =Raw_Data!F75 -> 1 | G72: =E72*F72 -> 1799 | H72: =PROPER(TRIM(Raw_Data!H75)) -> Anjali Verma | I72: =PROPER(TRIM(Raw_Data!I75)) -> Mumbai | J72: =TRIM(Raw_Data!J75) -> Debit Card | K72: =PROPER(TRIM(Raw_Data!K75)) -> Shipped | L72: =TEXT(B72,"MMM") -> Sep | M72: =TEXT(B72,"ddd") -> Sat | N72: =IF(K72="Delivered","Delivered",IF(K72="Cancelled","Cancelled","Pending")) -> Pending | O72: =IF(ROUND(G72-Raw_Data!G75,2)=0,"OK","Corrected") -> OK
A73: =TRIM(Raw_Data!A77) -> AMZ-10008 | B73: =Raw_Data!B77 -> 46270 | C73: =PROPER(TRIM(Raw_Data!C77)) -> Power Bank | D73: =TRIM(Raw_Data!D77) -> Electronics | E73: =Raw_Data!E77 -> 1299 | F73: =Raw_Data!F77 -> 1 | G73: =E73*F73 -> 1299 | H73: =PROPER(TRIM(Raw_Data!H77)) -> Priya Chopra | I73: =PROPER(TRIM(Raw_Data!I77)) -> Bangalore | J73: =TRIM(Raw_Data!J77) -> Debit Card | K73: =PROPER(TRIM(Raw_Data!K77)) -> Pending | L73: =TEXT(B73,"MMM") -> Sep | M73: =TEXT(B73,"ddd") -> Sat | N73: =IF(K73="Delivered","Delivered",IF(K73="Cancelled","Cancelled","Pending")) -> Pending | O73: =IF(ROUND(G73-Raw_Data!G77,2)=0,"OK","Corrected") -> OK
A74: =TRIM(Raw_Data!A78) -> AMZ-10029 | B74: =Raw_Data!B78 -> 46270 | C74: =PROPER(TRIM(Raw_Data!C78)) -> Smart Watch | D74: =TRIM(Raw_Data!D78) -> Electronics | E74: =Raw_Data!E78 -> 4999 | F74: =Raw_Data!F78 -> 1 | G74: =E74*F74 -> 4999 | H74: =PROPER(TRIM(Raw_Data!H78)) -> Priya Das | I74: =PROPER(TRIM(Raw_Data!I78)) -> Hyderabad | J74: =TRIM(Raw_Data!J78) -> UPI | K74: =PROPER(TRIM(Raw_Data!K78)) -> Delivered | L74: =TEXT(B74,"MMM") -> Sep | M74: =TEXT(B74,"ddd") -> Sat | N74: =IF(K74="Delivered","Delivered",IF(K74="Cancelled","Cancelled","Pending")) -> Delivered | O74: =IF(ROUND(G74-Raw_Data!G78,2)=0,"OK","Corrected") -> OK
A75: =TRIM(Raw_Data!A79) -> AMZ-10037 | B75: =Raw_Data!B79 -> 46270 | C75: =PROPER(TRIM(Raw_Data!C79)) -> Cotton T-Shirt | D75: =TRIM(Raw_Data!D79) -> Clothing | E75: =Raw_Data!E79 -> 599 | F75: =Raw_Data!F79 -> 4 | G75: =E75*F75 -> 2396 | H75: =PROPER(TRIM(Raw_Data!H79)) -> Suresh Nair | I75: =PROPER(TRIM(Raw_Data!I79)) -> Bangalore | J75: =TRIM(Raw_Data!J79) -> Net Banking | K75: =PROPER(TRIM(Raw_Data!K79)) -> Delivered | L75: =TEXT(B75,"MMM") -> Sep | M75: =TEXT(B75,"ddd") -> Sat | N75: =IF(K75="Delivered","Delivered",IF(K75="Cancelled","Cancelled","Pending")) -> Delivered | O75: =IF(ROUND(G75-Raw_Data!G79,2)=0,"OK","Corrected") -> OK
A76: =TRIM(Raw_Data!A80) -> AMZ-10056 | B76: =Raw_Data!B80 -> 46270 | C76: =PROPER(TRIM(Raw_Data!C80)) -> Water Bottle | D76: =TRIM(Raw_Data!D80) -> Home & Kitchen | E76: =Raw_Data!E80 -> 499 | F76: =Raw_Data!F80 -> 1 | G76: =E76*F76 -> 499 | H76: =PROPER(TRIM(Raw_Data!H80)) -> Arjun Verma | I76: =PROPER(TRIM(Raw_Data!I80)) -> Pune | J76: =TRIM(Raw_Data!J80) -> UPI | K76: =PROPER(TRIM(Raw_Data!K80)) -> Delivered | L76: =TEXT(B76,"MMM") -> Sep | M76: =TEXT(B76,"ddd") -> Sat | N76: =IF(K76="Delivered","Delivered",IF(K76="Cancelled","Cancelled","Pending")) -> Delivered | O76: =IF(ROUND(G76-Raw_Data!G80,2)=0,"OK","Corrected") -> OK
A77: =TRIM(Raw_Data!A81) -> AMZ-10100 | B77: =Raw_Data!B81 -> 46270 | C77: =PROPER(TRIM(Raw_Data!C81)) -> Bluetooth Speaker | D77: =TRIM(Raw_Data!D81) -> Electronics | E77: =Raw_Data!E81 -> 1999 | F77: =Raw_Data!F81 -> 1 | G77: =E77*F77 -> 1999 | H77: =PROPER(TRIM(Raw_Data!H81)) -> Priya Chopra | I77: =PROPER(TRIM(Raw_Data!I81)) -> Bangalore | J77: =TRIM(Raw_Data!J81) -> UPI | K77: =PROPER(TRIM(Raw_Data!K81)) -> Shipped | L77: =TEXT(B77,"MMM") -> Sep | M77: =TEXT(B77,"ddd") -> Sat | N77: =IF(K77="Delivered","Delivered",IF(K77="Cancelled","Cancelled","Pending")) -> Pending | O77: =IF(ROUND(G77-Raw_Data!G81,2)=0,"OK","Corrected") -> OK
A78: =TRIM(Raw_Data!A82) -> AMZ-10104 | B78: =Raw_Data!B82 -> 46270 | C78: =PROPER(TRIM(Raw_Data!C82)) -> Wireless Earbuds | D78: =TRIM(Raw_Data!D82) -> Electronics | E78: =Raw_Data!E82 -> 2499 | F78: =Raw_Data!F82 -> 2 | G78: =E78*F78 -> 4998 | H78: =PROPER(TRIM(Raw_Data!H82)) -> Aditya Kulkarni | I78: =PROPER(TRIM(Raw_Data!I82)) -> Bangalore | J78: =TRIM(Raw_Data!J82) -> UPI | K78: =PROPER(TRIM(Raw_Data!K82)) -> Delivered | L78: =TEXT(B78,"MMM") -> Sep | M78: =TEXT(B78,"ddd") -> Sat | N78: =IF(K78="Delivered","Delivered",IF(K78="Cancelled","Cancelled","Pending")) -> Delivered | O78: =IF(ROUND(G78-Raw_Data!G82,2)=0,"OK","Corrected") -> OK
A79: =TRIM(Raw_Data!A83) -> AMZ-10125 | B79: =Raw_Data!B83 -> 46270 | C79: =PROPER(TRIM(Raw_Data!C83)) -> Python Programming Book | D79: =TRIM(Raw_Data!D83) -> Books | E79: =Raw_Data!E83 -> 699 | F79: =Raw_Data!F83 -> 1 | G79: =E79*F79 -> 699 | H79: =PROPER(TRIM(Raw_Data!H83)) -> Priya Das | I79: =PROPER(TRIM(Raw_Data!I83)) -> Hyderabad | J79: =TRIM(Raw_Data!J83) -> Net Banking | K79: =PROPER(TRIM(Raw_Data!K83)) -> Delivered | L79: =TEXT(B79,"MMM") -> Sep | M79: =TEXT(B79,"ddd") -> Sat | N79: =IF(K79="Delivered","Delivered",IF(K79="Cancelled","Cancelled","Pending")) -> Delivered | O79: =IF(ROUND(G79-Raw_Data!G83,2)=0,"OK","Corrected") -> OK
A80: =TRIM(Raw_Data!A84) -> AMZ-10133 | B80: =Raw_Data!B84 -> 46270 | C80: =PROPER(TRIM(Raw_Data!C84)) -> Mixer Grinder | D80: =TRIM(Raw_Data!D84) -> Home & Kitchen | E80: =Raw_Data!E84 -> 3499 | F80: =Raw_Data!F84 -> 2 | G80: =E80*F80 -> 6998 | H80: =PROPER(TRIM(Raw_Data!H84)) -> Vikram Reddy | I80: =PROPER(TRIM(Raw_Data!I84)) -> Hyderabad | J80: =TRIM(Raw_Data!J84) -> Credit Card | K80: =PROPER(TRIM(Raw_Data!K84)) -> Delivered | L80: =TEXT(B80,"MMM") -> Sep | M80: =TEXT(B80,"ddd") -> Sat | N80: =IF(K80="Delivered","Delivered",IF(K80="Cancelled","Cancelled","Pending")) -> Delivered | O80: =IF(ROUND(G80-Raw_Data!G84,2)=0,"OK","Corrected") -> OK
A81: =TRIM(Raw_Data!A85) -> AMZ-10161 | B81: =Raw_Data!B85 -> 46270 | C81: =PROPER(TRIM(Raw_Data!C85)) -> Self Help Book | D81: =TRIM(Raw_Data!D85) -> Books | E81: =Raw_Data!E85 -> 399 | F81: =Raw_Data!F85 -> 1 | G81: =E81*F81 -> 399 | H81: =PROPER(TRIM(Raw_Data!H85)) -> Aditya Rao | I81: =PROPER(TRIM(Raw_Data!I85)) -> Delhi | J81: =TRIM(Raw_Data!J85) -> Debit Card | K81: =PROPER(TRIM(Raw_Data!K85)) -> Delivered | L81: =TEXT(B81,"MMM") -> Sep | M81: =TEXT(B81,"ddd") -> Sat | N81: =IF(K81="Delivered","Delivered",IF(K81="Cancelled","Cancelled","Pending")) -> Delivered | O81: =IF(ROUND(G81-Raw_Data!G85,2)=0,"OK","Corrected") -> OK
A82: =TRIM(Raw_Data!A86) -> AMZ-10176 | B82: =Raw_Data!B86 -> 46270 | C82: =PROPER(TRIM(Raw_Data!C86)) -> Self Help Book | D82: =TRIM(Raw_Data!D86) -> Books | E82: =Raw_Data!E86 -> 399 | F82: =Raw_Data!F86 -> 1 | G82: =E82*F82 -> 399 | H82: =PROPER(TRIM(Raw_Data!H86)) -> Tanvi Iyer | I82: =PROPER(TRIM(Raw_Data!I86)) -> Kolkata | J82: =TRIM(Raw_Data!J86) -> Cash On Delivery | K82: =PROPER(TRIM(Raw_Data!K86)) -> Delivered | L82: =TEXT(B82,"MMM") -> Sep | M82: =TEXT(B82,"ddd") -> Sat | N82: =IF(K82="Delivered","Delivered",IF(K82="Cancelled","Cancelled","Pending")) -> Delivered | O82: =IF(ROUND(G82-Raw_Data!G86,2)=0,"OK","Corrected") -> OK
...

Sheet Raw_Data
A1: Order ID | B1: Date | C1: Product | D1: Category | E1: Price | F1: Quantity | G1: Total Sales | H1: Customer Name | I1: Customer Location | J1: Payment Method | K1: Order Status
A2: AMZ-10052 | B2: 46266 | C2: mixer grinder | D2: Home & Kitchen | E2: 3499 | F2: 1 | G2: 3499 | H2: Vikram Joshi | I2: Hyderabad | J2: UPI | K2: Delivered
A3: AMZ-10123 | B3: 46266 | C3: SELF HELP BOOK | D3: Books | E3: 399 | F3: 3 | G3: 1197 | H3: Vikram Iyer | I3: Bangalore | J3: Debit Card | K3: Delivered
A4: AMZ-10196 | B4: 46266 | C4: Water Bottle | D4: Home & Kitchen | E4: 499 | F4: 2 | G4: 998 | H4: Priya Das | I4: Hyderabad | J4: Debit Card | K4: Delivered
A5: AMZ-10245 | B5: 46266 | C5: Self Help Book | D5: Books | E5: 399 | F5: 3 | G5: 1197 | H5: Vivaan Sharma | I5: Mumbai | J5: Credit Card | K5: Delivered
A6: AMZ-10252 | B6: 46266 | C6: Cotton T-Shirt | D6: Clothing | E6: 599 | F6: 1 | G6: 599 | H6: Priya Chopra | I6: bangalore | J6: Debit Card | K6: Delivered
A7: AMZ-10255 | B7: 46266 | C7: Sandals | D7: Footwear | E7: 899 | F7: 4 | G7: 3596 | H7: Priya Das | I7: HYDERABAD | J7: Credit Card | K7: Delivered
A8: AMZ-10255 | B8: 46266 | C8: Sandals | D8: Footwear | E8: 899 | F8: 4 | G8: 3596 | H8: Priya Das | I8: HYDERABAD | J8: Credit Card | K8: Delivered
A9: AMZ-10301 | B9: 46266 | C9: Sandals | D9: Footwear | E9: 899 | F9: 3 | G9: 2697 | H9: Nikhil Reddy | I9: Chennai | J9: UPI | K9: Delivered
A10: AMZ-10301 | B10: 46266 | C10: Sandals | D10: Footwear | E10: 899 | F10: 3 | G10: 2697 | H10: Nikhil Reddy | I10: Chennai | J10: UPI | K10: Delivered
A11: AMZ-10364 | B11: 46266 | C11: Water Bottle | D11: Home & Kitchen | E11: 499 | F11: 3 | G11: 1497 | H11: VIVAAN DAS | I11: Ahmedabad | J11: UPI | K11: Delivered
A12: AMZ-10414 | B12: 46266 | C12: Air Fryer | D12: Home & Kitchen | E12: 5999 | F12: 1 | G12: 5999 | H12: Aditya Singh | I12: Delhi | J12: UPI | K12: Delivered
A13: AMZ-10484 | B13: 46266 | C13: Water Bottle | D13: Home & Kitchen | E13: 499 | F13: 1 | G13: 499 | H13: Priya Iyer | I13: Delhi | J13: Debit Card | K13: Delivered
... A516: AMZ-10476 | B516: 46295 | C516: Denim Jeans | D516: Clothing | E516: 1799 | F516: 1 | G516: 1799 | H516: Sneha Reddy | I516: Pune | J516: UPI | K516: Delivered

Sheet Insights
B1: Insights & Recommendations
B2: Computed from ALL data (not affected by Dashboard filters). Text updates automatically if the data changes.
B4: Question | C4: Finding
B5: Highest-selling product | C5: =INDEX(Pivots!$A$21:$A$34,MATCH(MAX(Pivots!$F$21:$F$34),Pivots!$F$21:$F$34,0))&" (₹"&TEXT(MAX(Pivots!$F$21:$F$34),"#,##0")&")"&" – "&TEXT(MAX(Pivots!$F$21:$F$34)/Pivots!$F$35,"0.0%")&" of total sales" -> Smart Watch (₹2,34,953) – 15.0% of total sales
B6: Lowest-selling product | C6: =INDEX(Pivots!$A$21:$A$34,MATCH(MIN(Pivots!$F$21:$F$34),Pivots!$F$21:$F$34,0))&" (₹"&TEXT(MIN(Pivots!$F$21:$F$34),"#,##0")&")" -> Self Help Book (₹27,531)
B7: Best category | C7: =INDEX(Pivots!$A$11:$A$15,MATCH(MAX(Pivots!$F$11:$F$15),Pivots!$F$11:$F$15,0))&" (₹"&TEXT(MAX(Pivots!$F$11:$F$15),"#,##0")&")"&" – "&TEXT(MAX(Pivots!$F$11:$F$15)/Pivots!$F$16,"0.0%")&" of total sales" -> Electronics (₹5,95,070) – 38.0% of total sales
B8: Weakest category | C8: =INDEX(Pivots!$A$11:$A$15,MATCH(MIN(Pivots!$F$11:$F$15),Pivots!$F$11:$F$15,0))&" (₹"&TEXT(MIN(Pivots!$F$11:$F$15),"#,##0")&")"&" – "&TEXT(MIN(Pivots!$F$11:$F$15)/Pivots!$F$16,"0.0%")&" of total sales" -> Books (₹60,384) – 3.9% of total sales
B9: Strongest city | C9: =INDEX(Pivots!$A$40:$A$49,MATCH(MAX(Pivots!$F$40:$F$49),Pivots!$F$40:$F$49,0))&" (₹"&TEXT(MAX(Pivots!$F$40:$F$49),"#,##0")&")"&" – "&TEXT(MAX(Pivots!$F$40:$F$49)/Pivots!$F$50,"0.0%")&" of total sales" -> Mumbai (₹3,51,454) – 22.5% of total sales
B10: Weakest city | C10: =INDEX(Pivots!$A$40:$A$49,MATCH(MIN(Pivots!$F$40:$F$49),Pivots!$F$40:$F$49,0))&" (₹"&TEXT(MIN(Pivots!$F$40:$F$49),"#,##0")&")"&" – "&TEXT(MIN(Pivots!$F$40:$F$49)/Pivots!$F$50,"0.0%")&" of total sales" -> Jaipur (₹27,381) – 1.7% of total sales
B11: Most-used payment method (by sales) | C11: =INDEX(Pivots!$A$55:$A$59,MATCH(MAX(Pivots!$F$55:$F$59),Pivots!$F$55:$F$59,0))&" (₹"&TEXT(MAX(Pivots!$F$55:$F$59),"#,##0")&")"&" – "&TEXT(MAX(Pivots!$F$55:$F$59)/Pivots!$F$60,"0.0%")&" of total sales" -> UPI (₹5,52,508) – 35.3% of total sales
B12: Order status split | C12: ="Delivered "&TEXT(COUNTIFS(Cleaned_Data!$N$2:$N$501,"Delivered")/COUNTA(Cleaned_Data!$A$2:$A$501),"0.0%")&" | Cancelled "&TEXT(COUNTIFS(Cleaned_Data!$N$2:$N$501,"Cancelled")/COUNTA(Cleaned_Data!$A$2:$A$501),"0.0%")&" | Pending/Shipped "&TEXT(COUNTIFS(Cleaned_Data!$N$2:$N$501,"Pending")/COUNTA(Cleaned_Data!$A$2:$A$501),"0.0%") -> Delivered 76.4% | Cancelled 12.6% | Pending/Shipped 11.0%
B13: Delivered : Cancelled ratio | C13: =TEXT(COUNTIFS(Cleaned_Data!$N$2:$N$501,"Delivered")/COUNTIFS(Cleaned_Data!$N$2:$N$501,"Cancelled"),"0.0")&" delivered for every 1 cancelled order" -> 6.1 delivered for every 1 cancelled order
B14: Total sales lost to cancellations | C14: ="₹"&TEXT(SUMIFS(Cleaned_Data!$G$2:$G$501,Cleaned_Data!$N$2:$N$501,"Cancelled"),"#,##0")&" ("&TEXT(SUMIFS(Cleaned_Data!$G$2:$G$501,Cleaned_Data!$N$2:$N$501,"Cancelled")/SUM(Cleaned_Data!$G$2:$G$501),"0.0%")&" of gross sales)" -> ₹2,12,492 (13.6% of gross sales)
B15: Top customer | C15: =Pivots!$J$11&" – ₹"&TEXT(Pivots!$K$11,"#,##0") -> Anjali Verma – ₹59,983
B17: Recommendations
B18: 1. Keep top products and best category well stocked and advertised; they drive the largest share of revenue.
B19: 2. Investigate the weakest cities and categories – test local promotions, faster delivery options or price changes.
B20: 3. Reduce cancellations: review the cancelled orders by product/city, tighten stock accuracy and confirm Cash On Delivery orders before dispatch.
B21: 4. Follow up on Pending/Shipped orders so they convert to Delivered within the promised window.
B22: 5. Promote the most-used digital payment methods (e.g. UPI offers) and nudge COD customers to prepay.
B23: 6. Run loyalty / repeat-purchase offers for the top-10 customers who contribute a disproportionate share of sales.

Sheet README
B1: Amazon Sales Performance Analysis – Excel Project
B3: IMPORTANT – sample data | C3: The original Google Drive dataset could not be opened here, so Raw_Data contains a generated SAMPLE dataset (one month, Sep 2026, same columns as the case study + Payment Method and Order Status). To use your real data: paste it into Raw_Data (same column order, starting A2), then extend the Cleaned_Data formulas down to match the row count.
B4: Sheets | C4: Dashboard → KPIs, 6 charts, 4 dropdown filters (Category, Location, Order Status, Month) Pivots → Category, Product, City, Payment, Status, Customer summary tables + Top 10 customers Cleaned_Data → formula-cleaned copy of Raw_Data with calculated fields Raw_Data → data as received (duplicates, stray spaces, mixed case, wrong totals) Insights → auto-updating findings and recommendations
B5: Data cleaning done | C5: • Removed 15 duplicate orders (Raw_Data has 515 rows → Cleaned_Data has 500) • TRIM / PROPER applied to Product, Customer Name, Location, Status; TRIM on Order ID, Category, Payment • Dates stored as real dates; Price, Quantity, Total Sales as numbers • Total Sales recalculated as Price × Quantity; Validation column shows 'Corrected' where Raw_Data's total was wrong
B6: Calculated fields | C6: Month =TEXT(Date,"MMM") · Day of Week =TEXT(Date,"ddd") · Status Flag groups Shipped with Pending (Delivered / Cancelled / Pending)
B7: About the 'PivotTables' | C7: The summary tables on the Pivots sheet are built with SUMIFS/COUNTIFS so they are fully formula-driven and respond to the Dashboard dropdowns. If you want native PivotTables/Slicers, select Cleaned_Data → Insert → PivotTable and Insert → Slicer.
B8: Notes | C8: Total Sales includes all orders (also cancelled). Order Status table ignores the Status filter. 'All' = no filter. Yellow cells = inputs.
